Workbook

Sheet Data Entry
B1: Cash Runway Stress Tester — Analyst Data Entry
B2: Paste or type client inputs here. Yellow = data from client file. All monetary values in ₹ Cr.
B4: Input Field | C4: Client Value | D4: Guidance / Source
B5: A. CLIENT PROFILE
B6: Company Name | D6: Client Input File · Cover Sheet
B7: Industry / Sector | D7: Client Input File · Cover Sheet
B8: Analysis Date | D8: Enter today's date
B9: Analyst Name | D9: PROFYT Analyst conducting this review
B11: B. CASH POSITION (₹ Crore)
B12: Cash & Bank Balance | C12: 0 | D12: Client Input File · Section B · Row 1
B13: Short-Term Investments / FDs | C13: 0 | D13: Client Input File · Section B · Row 2
B14: Total Accessible Cash | C14: =IFERROR(C12+C13,0) -> 0 | D14: AUTO — Sum of above
B15: Accounts Receivable (< 60 days) | C15: 0 | D15: Client Input File · Section B · Row 4
B16: Undrawn Credit Facility | C16: 0 | D16: Client Input File · Section B · Row 5
B18: C. MONTHLY REVENUE (₹ Crore / month)
B19: Primary Revenue Stream | C19: 0 | D19: Client Input File · Section C · Row 1
B20: Secondary Revenue Stream | C20: 0 | D20: Client Input File · Section C · Row 2
B21: Tertiary Revenue Stream | C21: 0 | D21: Client Input File · Section C · Row 3
B22: Other / Misc Revenue | C22: 0 | D22: Client Input File · Section C · Row 4
B23: TOTAL MONTHLY REVENUE | C23: =IFERROR(SUM(C19:C22),0) -> 0 | D23: AUTO — Sum of revenue streams
B25: D. MONTHLY EXPENSES / BURN (₹ Crore / month)
B26: Salaries & Benefits | C26: 0 | D26: Client Input File · Section D
B27: Cloud, Tech & SaaS | C27: 0 | D27: Client Input File · Section D
B28: Marketing & Acquisition Spend | C28: 0 | D28: Client Input File · Section D
B29: Rent & Facilities | C29: 0 | D29: Client Input File · Section D
B30: Cost of Delivery / COGS | C30: 0 | D30: Client Input File · Section D
B31: Professional Fees | C31: 0 | D31: Client Input File · Section D
B32: Loan / Debt EMI | C32: 0 | D32: Client Input File · Section D
B33: Other Fixed Expenses | C33: 0 | D33: Client Input File · Section D
B34: Other Variable Expenses | C34: 0 | D34: Client Input File · Section D
B35: TOTAL MONTHLY BURN | C35: =IFERROR(SUM(C26:C34),0) -> 0 | D35: AUTO — Sum of all expense lines
B37: E. GROWTH RATES & STRESS SCENARIO ASSUMPTIONS
B38: Base = client's own estimates. Downside & Worst Case = PROFYT analyst stress inputs.
B39: Assumption | C39: Base Case (client input) | D39: Analyst Override (optional)
B40: Monthly Revenue Growth Rate (%) | C40: 0
B41: Monthly Burn Growth Rate (%) | C41: 0
B43: Stress Assumption | C43: Downside (₹ Cr or %) | D43: Worst Case (₹ Cr or %)
B44: Revenue Drop vs Base (% reduction) | C44: 0 | D44: 0
B45: Burn Spike vs Base (% increase) | C45: 0 | D45: 0
B47: F. ONE-TIME CASH EVENTS
...

Sheet Scenario Model
B1: Scenario Model — 12-Month Cash Projection (3 Scenarios)
C2: BASE CASE | P2: DOWNSIDE | AC2: WORST CASE
B3: ₹ Crore | C3: Mo 1 | D3: Mo 2 | E3: Mo 3 | F3: Mo 4 | G3: Mo 5 | H3: Mo 6 | I3: Mo 7 | J3: Mo 8 | K3: Mo 9 | L3: Mo 10 | M3: Mo 11 | N3: Mo 12 | P3: Mo 1 | Q3: Mo 2 | R3: Mo 3 | S3: Mo 4 | T3: Mo 5 | U3: Mo 6 | V3: Mo 7 | W3: Mo 8 | X3: Mo 9 | Y3: Mo 10 | Z3: Mo 11 | AA3: Mo 12 | AC3: Mo 1 | AD3: Mo 2 | AE3: Mo 3 | AF3: Mo 4 | AG3: Mo 5 | AH3: Mo 6 | AI3: Mo 7 | AJ3: Mo 8 | AK3: Mo 9 | AL3: Mo 10 | AM3: Mo 11 | AN3: Mo 12
B4: Opening Cash (₹ Cr) | C4: ='Data Entry'!C14 -> 0 | D4: =IFERROR(C10,0) -> 0 | E4: =IFERROR(D10,0) -> 0 | F4: =IFERROR(E10,0) -> 0 | G4: =IFERROR(F10,0) -> 0 | H4: =IFERROR(G10,0) -> 0 | I4: =IFERROR(H10,0) -> 0 | J4: =IFERROR(I10,0) -> 0 | K4: =IFERROR(J10,0) -> 0 | ... N4: =IFERROR(M10,0) -> 0 | P4: ='Data Entry'!C14 -> 0 | Q4: =IFERROR(P10,0) -> 0 | R4: =IFERROR(Q10,0) -> 0 | S4: =IFERROR(R10,0) -> 0 | T4: =IFERROR(S10,0) -> 0 | U4: =IFERROR(T10,0) -> 0 | V4: =IFERROR(U10,0) -> 0 | W4: =IFERROR(V10,0) -> 0 | X4: =IFERROR(W10,0) -> 0 | ... AA4: =IFERROR(Z10,0) -> 0 | AC4: ='Data Entry'!C14 -> 0 | AD4: =IFERROR(AC10,0) -> 0 | AE4: =IFERROR(AD10,0) -> 0 | AF4: =IFERROR(AE10,0) -> 0 | AG4: =IFERROR(AF10,0) -> 0 | AH4: =IFERROR(AG10,0) -> 0 | AI4: =IFERROR(AH10,0) -> 0 | AJ4: =IFERROR(AI10,0) -> 0 | AK4: =IFERROR(AJ10,0) -> 0 | ... AN4: =IFERROR(AM10,0) -> 0
B5: Monthly Revenue (₹ Cr) | C5: =IFERROR(('Data Entry'!C23*(1+'Data Entry'!C40)^0)*(1-0),0) -> 0 | D5: =IFERROR(('Data Entry'!C23*(1+'Data Entry'!C40)^1)*(1-0),0) -> 0 | E5: =IFERROR(('Data Entry'!C23*(1+'Data Entry'!C40)^2)*(1-0),0) -> 0 | F5: =IFERROR(('Data Entry'!C23*(1+'Data Entry'!C40)^3)*(1-0),0) -> 0 | G5: =IFERROR(('Data Entry'!C23*(1+'Data Entry'!C40)^4)*(1-0),0) -> 0 | H5: =IFERROR(('Data Entry'!C23*(1+'Data Entry'!C40)^5)*(1-0),0) -> 0 | I5: =IFERROR(('Data Entry'!C23*(1+'Data Entry'!C40)^6)*(1-0),0) -> 0 | J5: =IFERROR(('Data Entry'!C23*(1+'Data Entry'!C40)^7)*(1-0),0) -> 0 | K5: =IFERROR(('Data Entry'!C23*(1+'Data Entry'!C40)^8)*(1-0),0) -> 0 | L5: =IFERROR(('Data Entry'!C23*(1+'Data Entry'!C40)^9)*(1-0),0) -> 0 | M5: =IFERROR(('Data Entry'!C23*(1+'Data Entry'!C40)^10)*(1-0),0) -> 0 | N5: =IFERROR(('Data Entry'!C23*(1+'Data Entry'!C40)^11)*(1-0),0) -> 0 | P5: =IFERROR(('Data Entry'!C23*(1+'Data Entry'!C40)^0)*(1-'Data Entry'!C44),0) -> 0 | Q5: =IFERROR(('Data Entry'!C23*(1+'Data Entry'!C40)^1)*(1-'Data Entry'!C44),0) -> 0 | R5: =IFERROR(('Data Entry'!C23*(1+'Data Entry'!C40)^2)*(1-'Data Entry'!C44),0) -> 0 | S5: =IFERROR(('Data Entry'!C23*(1+'Data Entry'!C40)^3)*(1-'Data Entry'!C44),0) -> 0 | T5: =IFERROR(('Data Entry'!C23*(1+'Data Entry'!C40)^4)*(1-'Data Entry'!C44),0) -> 0 | U5: =IFERROR(('Data Entry'!C23*(1+'Data Entry'!C40)^5)*(1-'Data Entry'!C44),0) -> 0 | V5: =IFERROR(('Data Entry'!C23*(1+'Data Entry'!C40)^6)*(1-'Data Entry'!C44),0) -> 0 | W5: =IFERROR(('Data Entry'!C23*(1+'Data Entry'!C40)^7)*(1-'Data Entry'!C44),0) -> 0 | X5: =IFERROR(('Data Entry'!C23*(1+'Data Entry'!C40)^8)*(1-'Data Entry'!C44),0) -> 0 | Y5: =IFERROR(('Data Entry'!C23*(1+'Data Entry'!C40)^9)*(1-'Data Entry'!C44),0) -> 0 | Z5: =IFERROR(('Data Entry'!C23*(1+'Data Entry'!C40)^10)*(1-'Data Entry'!C44),0) -> 0 | AA5: =IFERROR(('Data Entry'!C23*(1+'Data Entry'!C40)^11)*(1-'Data Entry'!C44),0) -> 0 | AC5: =IFERROR(('Data Entry'!C23*(1+'Data Entry'!C40)^0)*(1-'Data Entry'!D44),0) -> 0 | AD5: =IFERROR(('Data Entry'!C23*(1+'Data Entry'!C40)^1)*(1-'Data Entry'!D44),0) -> 0 | AE5: =IFERROR(('Data Entry'!C23*(1+'Data Entry'!C40)^2)*(1-'Data Entry'!D44),0) -> 0 | AF5: =IFERROR(('Data Entry'!C23*(1+'Data Entry'!C40)^3)*(1-'Data Entry'!D44),0) -> 0 | AG5: =IFERROR(('Data Entry'!C23*(1+'Data Entry'!C40)^4)*(1-'Data Entry'!D44),0) -> 0 | AH5: =IFERROR(('Data Entry'!C23*(1+'Data Entry'!C40)^5)*(1-'Data Entry'!D44),0) -> 0 | AI5: =IFERROR(('Data Entry'!C23*(1+'Data Entry'!C40)^6)*(1-'Data Entry'!D44),0) -> 0 | AJ5: =IFERROR(('Data Entry'!C23*(1+'Data Entry'!C40)^7)*(1-'Data Entry'!D44),0) -> 0 | AK5: =IFERROR(('Data Entry'!C23*(1+'Data Entry'!C40)^8)*(1-'Data Entry'!D44),0) -> 0 | AL5: =IFERROR(('Data Entry'!C23*(1+'Data Entry'!C40)^9)*(1-'Data Entry'!D44),0) -> 0 | AM5: =IFERROR(('Data Entry'!C23*(1+'Data Entry'!C40)^10)*(1-'Data Entry'!D44),0) -> 0 | AN5: =IFERROR(('Data Entry'!C23*(1+'Data Entry'!C40)^11)*(1-'Data Entry'!D44),0) -> 0
B6: Monthly Burn (₹ Cr) | C6: =IFERROR(('Data Entry'!C35*(1+'Data Entry'!C41)^0)*(1+0),0) -> 0 | D6: =IFERROR(('Data Entry'!C35*(1+'Data Entry'!C41)^1)*(1+0),0) -> 0 | E6: =IFERROR(('Data Entry'!C35*(1+'Data Entry'!C41)^2)*(1+0),0) -> 0 | F6: =IFERROR(('Data Entry'!C35*(1+'Data Entry'!C41)^3)*(1+0),0) -> 0 | G6: =IFERROR(('Data Entry'!C35*(1+'Data Entry'!C41)^4)*(1+0),0) -> 0 | H6: =IFERROR(('Data Entry'!C35*(1+'Data Entry'!C41)^5)*(1+0),0) -> 0 | I6: =IFERROR(('Data Entry'!C35*(1+'Data Entry'!C41)^6)*(1+0),0) -> 0 | J6: =IFERROR(('Data Entry'!C35*(1+'Data Entry'!C41)^7)*(1+0),0) -> 0 | K6: =IFERROR(('Data Entry'!C35*(1+'Data Entry'!C41)^8)*(1+0),0) -> 0 | L6: =IFERROR(('Data Entry'!C35*(1+'Data Entry'!C41)^9)*(1+0),0) -> 0 | M6: =IFERROR(('Data Entry'!C35*(1+'Data Entry'!C41)^10)*(1+0),0) -> 0 | N6: =IFERROR(('Data Entry'!C35*(1+'Data Entry'!C41)^11)*(1+0),0) -> 0 | P6: =IFERROR(('Data Entry'!C35*(1+'Data Entry'!C41)^0)*(1+'Data Entry'!C45),0) -> 0 | Q6: =IFERROR(('Data Entry'!C35*(1+'Data Entry'!C41)^1)*(1+'Data Entry'!C45),0) -> 0 | R6: =IFERROR(('Data Entry'!C35*(1+'Data Entry'!C41)^2)*(1+'Data Entry'!C45),0) -> 0 | S6: =IFERROR(('Data Entry'!C35*(1+'Data Entry'!C41)^3)*(1+'Data Entry'!C45),0) -> 0 | T6: =IFERROR(('Data Entry'!C35*(1+'Data Entry'!C41)^4)*(1+'Data Entry'!C45),0) -> 0 | U6: =IFERROR(('Data Entry'!C35*(1+'Data Entry'!C41)^5)*(1+'Data Entry'!C45),0) -> 0 | V6: =IFERROR(('Data Entry'!C35*(1+'Data Entry'!C41)^6)*(1+'Data Entry'!C45),0) -> 0 | W6: =IFERROR(('Data Entry'!C35*(1+'Data Entry'!C41)^7)*(1+'Data Entry'!C45),0) -> 0 | X6: =IFERROR(('Data Entry'!C35*(1+'Data Entry'!C41)^8)*(1+'Data Entry'!C45),0) -> 0 | Y6: =IFERROR(('Data Entry'!C35*(1+'Data Entry'!C41)^9)*(1+'Data Entry'!C45),0) -> 0 | Z6: =IFERROR(('Data Entry'!C35*(1+'Data Entry'!C41)^10)*(1+'Data Entry'!C45),0) -> 0 | AA6: =IFERROR(('Data Entry'!C35*(1+'Data Entry'!C41)^11)*(1+'Data Entry'!C45),0) -> 0 | AC6: =IFERROR(('Data Entry'!C35*(1+'Data Entry'!C41)^0)*(1+'Data Entry'!D45),0) -> 0 | AD6: =IFERROR(('Data Entry'!C35*(1+'Data Entry'!C41)^1)*(1+'Data Entry'!D45),0) -> 0 | AE6: =IFERROR(('Data Entry'!C35*(1+'Data Entry'!C41)^2)*(1+'Data Entry'!D45),0) -> 0 | AF6: =IFERROR(('Data Entry'!C35*(1+'Data Entry'!C41)^3)*(1+'Data Entry'!D45),0) -> 0 | AG6: =IFERROR(('Data Entry'!C35*(1+'Data Entry'!C41)^4)*(1+'Data Entry'!D45),0) -> 0 | AH6: =IFERROR(('Data Entry'!C35*(1+'Data Entry'!C41)^5)*(1+'Data Entry'!D45),0) -> 0 | AI6: =IFERROR(('Data Entry'!C35*(1+'Data Entry'!C41)^6)*(1+'Data Entry'!D45),0) -> 0 | AJ6: =IFERROR(('Data Entry'!C35*(1+'Data Entry'!C41)^7)*(1+'Data Entry'!D45),0) -> 0 | AK6: =IFERROR(('Data Entry'!C35*(1+'Data Entry'!C41)^8)*(1+'Data Entry'!D45),0) -> 0 | AL6: =IFERROR(('Data Entry'!C35*(1+'Data Entry'!C41)^9)*(1+'Data Entry'!D45),0) -> 0 | AM6: =IFERROR(('Data Entry'!C35*(1+'Data Entry'!C41)^10)*(1+'Data Entry'!D45),0) -> 0 | AN6: =IFERROR(('Data Entry'!C35*(1+'Data Entry'!C41)^11)*(1+'Data Entry'!D45),0) -> 0
B7: One-Time Inflows (₹ Cr) | C7: =IFERROR(IF('Data Entry'!D49=1,'Data Entry'!C49,0)+IF('Data Entry'!D51=1,'Data Entry'!C51,0),0) -> 0 | D7: =IFERROR(IF('Data Entry'!D49=2,'Data Entry'!C49,0)+IF('Data Entry'!D51=2,'Data Entry'!C51,0),0) -> 0 | E7: =IFERROR(IF('Data Entry'!D49=3,'Data Entry'!C49,0)+IF('Data Entry'!D51=3,'Data Entry'!C51,0),0) -> 0 | F7: =IFERROR(IF('Data Entry'!D49=4,'Data Entry'!C49,0)+IF('Data Entry'!D51=4,'Data Entry'!C51,0),0) -> 0 | G7: =IFERROR(IF('Data Entry'!D49=5,'Data Entry'!C49,0)+IF('Data Entry'!D51=5,'Data Entry'!C51,0),0) -> 0 | H7: =IFERROR(IF('Data Entry'!D49=6,'Data Entry'!C49,0)+IF('Data Entry'!D51=6,'Data Entry'!C51,0),0) -> 0 | I7: =IFERROR(IF('Data Entry'!D49=7,'Data Entry'!C49,0)+IF('Data Entry'!D51=7,'Data Entry'!C51,0),0) -> 0 | J7: =IFERROR(IF('Data Entry'!D49=8,'Data Entry'!C49,0)+IF('Data Entry'!D51=8,'Data Entry'!C51,0),0) -> 0 | K7: =IFERROR(IF('Data Entry'!D49=9,'Data Entry'!C49,0)+IF('Data Entry'!D51=9,'Data Entry'!C51,0),0) -> 0 | L7: =IFERROR(IF('Data Entry'!D49=10,'Data Entry'!C49,0)+IF('Data Entry'!D51=10,'Data Entry'!C51,0),0) -> 0 | M7: =IFERROR(IF('Data Entry'!D49=11,'Data Entry'!C49,0)+IF('Data Entry'!D51=11,'Data Entry'!C51,0),0) -> 0 | N7: =IFERROR(IF('Data Entry'!D49=12,'Data Entry'!C49,0)+IF('Data Entry'!D51=12,'Data Entry'!C51,0),0) -> 0 | P7: =IFERROR(IF('Data Entry'!D49=1,'Data Entry'!C49,0)+IF('Data Entry'!D51=1,'Data Entry'!C51,0),0) -> 0 | Q7: =IFERROR(IF('Data Entry'!D49=2,'Data Entry'!C49,0)+IF('Data Entry'!D51=2,'Data Entry'!C51,0),0) -> 0 | R7: =IFERROR(IF('Data Entry'!D49=3,'Data Entry'!C49,0)+IF('Data Entry'!D51=3,'Data Entry'!C51,0),0) -> 0 | S7: =IFERROR(IF('Data Entry'!D49=4,'Data Entry'!C49,0)+IF('Data Entry'!D51=4,'Data Entry'!C51,0),0) -> 0 | T7: =IFERROR(IF('Data Entry'!D49=5,'Data Entry'!C49,0)+IF('Data Entry'!D51=5,'Data Entry'!C51,0),0) -> 0 | U7: =IFERROR(IF('Data Entry'!D49=6,'Data Entry'!C49,0)+IF('Data Entry'!D51=6,'Data Entry'!C51,0),0) -> 0 | V7: =IFERROR(IF('Data Entry'!D49=7,'Data Entry'!C49,0)+IF('Data Entry'!D51=7,'Data Entry'!C51,0),0) -> 0 | W7: =IFERROR(IF('Data Entry'!D49=8,'Data Entry'!C49,0)+IF('Data Entry'!D51=8,'Data Entry'!C51,0),0) -> 0 | X7: =IFERROR(IF('Data Entry'!D49=9,'Data Entry'!C49,0)+IF('Data Entry'!D51=9,'Data Entry'!C51,0),0) -> 0 | Y7: =IFERROR(IF('Data Entry'!D49=10,'Data Entry'!C49,0)+IF('Data Entry'!D51=10,'Data Entry'!C51,0),0) -> 0 | Z7: =IFERROR(IF('Data Entry'!D49=11,'Data Entry'!C49,0)+IF('Data Entry'!D51=11,'Data Entry'!C51,0),0) -> 0 | AA7: =IFERROR(IF('Data Entry'!D49=12,'Data Entry'!C49,0)+IF('Data Entry'!D51=12,'Data Entry'!C51,0),0) -> 0 | AC7: =IFERROR(IF('Data Entry'!D49=1,'Data Entry'!C49,0)+IF('Data Entry'!D51=1,'Data Entry'!C51,0),0) -> 0 | AD7: =IFERROR(IF('Data Entry'!D49=2,'Data Entry'!C49,0)+IF('Data Entry'!D51=2,'Data Entry'!C51,0),0) -> 0 | AE7: =IFERROR(IF('Data Entry'!D49=3,'Data Entry'!C49,0)+IF('Data Entry'!D51=3,'Data Entry'!C51,0),0) -> 0 | AF7: =IFERROR(IF('Data Entry'!D49=4,'Data Entry'!C49,0)+IF('Data Entry'!D51=4,'Data Entry'!C51,0),0) -> 0 | AG7: =IFERROR(IF('Data Entry'!D49=5,'Data Entry'!C49,0)+IF('Data Entry'!D51=5,'Data Entry'!C51,0),0) -> 0 | AH7: =IFERROR(IF('Data Entry'!D49=6,'Data Entry'!C49,0)+IF('Data Entry'!D51=6,'Data Entry'!C51,0),0) -> 0 | AI7: =IFERROR(IF('Data Entry'!D49=7,'Data Entry'!C49,0)+IF('Data Entry'!D51=7,'Data Entry'!C51,0),0) -> 0 | AJ7: =IFERROR(IF('Data Entry'!D49=8,'Data Entry'!C49,0)+IF('Data Entry'!D51=8,'Data Entry'!C51,0),0) -> 0 | AK7: =IFERROR(IF('Data Entry'!D49=9,'Data Entry'!C49,0)+IF('Data Entry'!D51=9,'Data Entry'!C51,0),0) -> 0 | AL7: =IFERROR(IF('Data Entry'!D49=10,'Data Entry'!C49,0)+IF('Data Entry'!D51=10,'Data Entry'!C51,0),0) -> 0 | AM7: =IFERROR(IF('Data Entry'!D49=11,'Data Entry'!C49,0)+IF('Data Entry'!D51=11,'Data Entry'!C51,0),0) -> 0 | AN7: =IFERROR(IF('Data Entry'!D49=12,'Data Entry'!C49,0)+IF('Data Entry'!D51=12,'Data Entry'!C51,0),0) -> 0
B8: One-Time Outflows (₹ Cr) | C8: =IFERROR(IF('Data Entry'!D50=1,'Data Entry'!C50,0),0) -> 0 | D8: =IFERROR(IF('Data Entry'!D50=2,'Data Entry'!C50,0),0) -> 0 | E8: =IFERROR(IF('Data Entry'!D50=3,'Data Entry'!C50,0),0) -> 0 | F8: =IFERROR(IF('Data Entry'!D50=4,'Data Entry'!C50,0),0) -> 0 | G8: =IFERROR(IF('Data Entry'!D50=5,'Data Entry'!C50,0),0) -> 0 | H8: =IFERROR(IF('Data Entry'!D50=6,'Data Entry'!C50,0),0) -> 0 | I8: =IFERROR(IF('Data Entry'!D50=7,'Data Entry'!C50,0),0) -> 0 | J8: =IFERROR(IF('Data Entry'!D50=8,'Data Entry'!C50,0),0) -> 0 | K8: =IFERROR(IF('Data Entry'!D50=9,'Data Entry'!C50,0),0) -> 0 | L8: =IFERROR(IF('Data Entry'!D50=10,'Data Entry'!C50,0),0) -> 0 | M8: =IFERROR(IF('Data Entry'!D50=11,'Data Entry'!C50,0),0) -> 0 | N8: =IFERROR(IF('Data Entry'!D50=12,'Data Entry'!C50,0),0) -> 0 | P8: =IFERROR(IF('Data Entry'!D50=1,'Data Entry'!C50,0),0) -> 0 | Q8: =IFERROR(IF('Data Entry'!D50=2,'Data Entry'!C50,0),0) -> 0 | R8: =IFERROR(IF('Data Entry'!D50=3,'Data Entry'!C50,0),0) -> 0 | S8: =IFERROR(IF('Data Entry'!D50=4,'Data Entry'!C50,0),0) -> 0 | T8: =IFERROR(IF('Data Entry'!D50=5,'Data Entry'!C50,0),0) -> 0 | U8: =IFERROR(IF('Data Entry'!D50=6,'Data Entry'!C50,0),0) -> 0 | V8: =IFERROR(IF('Data Entry'!D50=7,'Data Entry'!C50,0),0) -> 0 | W8: =IFERROR(IF('Data Entry'!D50=8,'Data Entry'!C50,0),0) -> 0 | X8: =IFERROR(IF('Data Entry'!D50=9,'Data Entry'!C50,0),0) -> 0 | Y8: =IFERROR(IF('Data Entry'!D50=10,'Data Entry'!C50,0),0) -> 0 | Z8: =IFERROR(IF('Data Entry'!D50=11,'Data Entry'!C50,0),0) -> 0 | AA8: =IFERROR(IF('Data Entry'!D50=12,'Data Entry'!C50,0),0) -> 0 | AC8: =IFERROR(IF('Data Entry'!D50=1,'Data Entry'!C50,0),0) -> 0 | AD8: =IFERROR(IF('Data Entry'!D50=2,'Data Entry'!C50,0),0) -> 0 | AE8: =IFERROR(IF('Data Entry'!D50=3,'Data Entry'!C50,0),0) -> 0 | AF8: =IFERROR(IF('Data Entry'!D50=4,'Data Entry'!C50,0),0) -> 0 | AG8: =IFERROR(IF('Data Entry'!D50=5,'Data Entry'!C50,0),0) -> 0 | AH8: =IFERROR(IF('Data Entry'!D50=6,'Data Entry'!C50,0),0) -> 0 | AI8: =IFERROR(IF('Data Entry'!D50=7,'Data Entry'!C50,0),0) -> 0 | AJ8: =IFERROR(IF('Data Entry'!D50=8,'Data Entry'!C50,0),0) -> 0 | AK8: =IFERROR(IF('Data Entry'!D50=9,'Data Entry'!C50,0),0) -> 0 | AL8: =IFERROR(IF('Data Entry'!D50=10,'Data Entry'!C50,0),0) -> 0 | AM8: =IFERROR(IF('Data Entry'!D50=11,'Data Entry'!C50,0),0) -> 0 | AN8: =IFERROR(IF('Data Entry'!D50=12,'Data Entry'!C50,0),0) -> 0
B9: Net Cash Movement (₹ Cr) | C9: =IFERROR(C5-C6+C7-C8,0) -> 0 | D9: =IFERROR(D5-D6+D7-D8,0) -> 0 | E9: =IFERROR(E5-E6+E7-E8,0) -> 0 | F9: =IFERROR(F5-F6+F7-F8,0) -> 0 | G9: =IFERROR(G5-G6+G7-G8,0) -> 0 | H9: =IFERROR(H5-H6+H7-H8,0) -> 0 | I9: =IFERROR(I5-I6+I7-I8,0) -> 0 | J9: =IFERROR(J5-J6+J7-J8,0) -> 0 | ... N9: =IFERROR(N5-N6+N7-N8,0) -> 0 | P9: =IFERROR(P5-P6+P7-P8,0) -> 0 | Q9: =IFERROR(Q5-Q6+Q7-Q8,0) -> 0 | R9: =IFERROR(R5-R6+R7-R8,0) -> 0 | S9: =IFERROR(S5-S6+S7-S8,0) -> 0 | T9: =IFERROR(T5-T6+T7-T8,0) -> 0 | U9: =IFERROR(U5-U6+U7-U8,0) -> 0 | V9: =IFERROR(V5-V6+V7-V8,0) -> 0 | W9: =IFERROR(W5-W6+W7-W8,0) -> 0 | ... AA9: =IFERROR(AA5-AA6+AA7-AA8,0) -> 0 | AC9: =IFERROR(AC5-AC6+AC7-AC8,0) -> 0 | AD9: =IFERROR(AD5-AD6+AD7-AD8,0) -> 0 | AE9: =IFERROR(AE5-AE6+AE7-AE8,0) -> 0 | AF9: =IFERROR(AF5-AF6+AF7-AF8,0) -> 0 | AG9: =IFERROR(AG5-AG6+AG7-AG8,0) -> 0 | AH9: =IFERROR(AH5-AH6+AH7-AH8,0) -> 0 | AI9: =IFERROR(AI5-AI6+AI7-AI8,0) -> 0 | AJ9: =IFERROR(AJ5-AJ6+AJ7-AJ8,0) -> 0 | ... AN9: =IFERROR(AN5-AN6+AN7-AN8,0) -> 0
B10: Closing Cash Balance (₹ Cr) | C10: =IFERROR(C4+C9,0) -> 0 | D10: =IFERROR(D4+D9,0) -> 0 | E10: =IFERROR(E4+E9,0) -> 0 | F10: =IFERROR(F4+F9,0) -> 0 | G10: =IFERROR(G4+G9,0) -> 0 | H10: =IFERROR(H4+H9,0) -> 0 | I10: =IFERROR(I4+I9,0) -> 0 | J10: =IFERROR(J4+J9,0) -> 0 | ... N10: =IFERROR(N4+N9,0) -> 0 | P10: =IFERROR(P4+P9,0) -> 0 | Q10: =IFERROR(Q4+Q9,0) -> 0 | R10: =IFERROR(R4+R9,0) -> 0 | S10: =IFERROR(S4+S9,0) -> 0 | T10: =IFERROR(T4+T9,0) -> 0 | U10: =IFERROR(U4+U9,0) -> 0 | V10: =IFERROR(V4+V9,0) -> 0 | W10: =IFERROR(W4+W9,0) -> 0 | ... AA10: =IFERROR(AA4+AA9,0) -> 0 | AC10: =IFERROR(AC4+AC9,0) -> 0 | AD10: =IFERROR(AD4+AD9,0) -> 0 | AE10: =IFERROR(AE4+AE9,0) -> 0 | AF10: =IFERROR(AF4+AF9,0) -> 0 | AG10: =IFERROR(AG4+AG9,0) -> 0 | AH10: =IFERROR(AH4+AH9,0) -> 0 | AI10: =IFERROR(AI4+AI9,0) -> 0 | AJ10: =IFERROR(AJ4+AJ9,0) -> 0 | ... AN10: =IFERROR(AN4+AN9,0) -> 0
B11: Cumulative Runway Used | C11: =IFERROR(IF(C10<=0,"⚠ ZERO","OK"),"") -> ⚠ ZERO | D11: =IFERROR(IF(D10<=0,"⚠ ZERO","OK"),"") -> ⚠ ZERO | E11: =IFERROR(IF(E10<=0,"⚠ ZERO","OK"),"") -> ⚠ ZERO | F11: =IFERROR(IF(F10<=0,"⚠ ZERO","OK"),"") -> ⚠ ZERO | G11: =IFERROR(IF(G10<=0,"⚠ ZERO","OK"),"") -> ⚠ ZERO | H11: =IFERROR(IF(H10<=0,"⚠ ZERO","OK"),"") -> ⚠ ZERO | I11: =IFERROR(IF(I10<=0,"⚠ ZERO","OK"),"") -> ⚠ ZERO | J11: =IFERROR(IF(J10<=0,"⚠ ZERO","OK"),"") -> ⚠ ZERO | ... N11: =IFERROR(IF(N10<=0,"⚠ ZERO","OK"),"") -> ⚠ ZERO | P11: =IFERROR(IF(P10<=0,"⚠ ZERO","OK"),"") -> ⚠ ZERO | Q11: =IFERROR(IF(Q10<=0,"⚠ ZERO","OK"),"") -> ⚠ ZERO | R11: =IFERROR(IF(R10<=0,"⚠ ZERO","OK"),"") -> ⚠ ZERO | S11: =IFERROR(IF(S10<=0,"⚠ ZERO","OK"),"") -> ⚠ ZERO | T11: =IFERROR(IF(T10<=0,"⚠ ZERO","OK"),"") -> ⚠ ZERO | U11: =IFERROR(IF(U10<=0,"⚠ ZERO","OK"),"") -> ⚠ ZERO | V11: =IFERROR(IF(V10<=0,"⚠ ZERO","OK"),"") -> ⚠ ZERO | W11: =IFERROR(IF(W10<=0,"⚠ ZERO","OK"),"") -> ⚠ ZERO | ... AA11: =IFERROR(IF(AA10<=0,"⚠ ZERO","OK"),"") -> ⚠ ZERO | AC11: =IFERROR(IF(AC10<=0,"⚠ ZERO","OK"),"") -> ⚠ ZERO | AD11: =IFERROR(IF(AD10<=0,"⚠ ZERO","OK"),"") -> ⚠ ZERO | AE11: =IFERROR(IF(AE10<=0,"⚠ ZERO","OK"),"") -> ⚠ ZERO | AF11: =IFERROR(IF(AF10<=0,"⚠ ZERO","OK"),"") -> ⚠ ZERO | AG11: =IFERROR(IF(AG10<=0,"⚠ ZERO","OK"),"") -> ⚠ ZERO | AH11: =IFERROR(IF(AH10<=0,"⚠ ZERO","OK"),"") -> ⚠ ZERO | AI11: =IFERROR(IF(AI10<=0,"⚠ ZERO","OK"),"") -> ⚠ ZERO | AJ11: =IFERROR(IF(AJ10<=0,"⚠ ZERO","OK"),"") -> ⚠ ZERO | ... AN11: =IFERROR(IF(AN10<=0,"⚠ ZERO","OK"),"") -> ⚠ ZERO

Sheet Dashboard
B1: Cash Runway Stress Tester — Dashboard
B2: Auto-calculated from Data Entry sheet. Complete Data Entry before reading this dashboard.
B4: KEY METRICS
B5: Metric | C5: Base Case | D5: Downside | E5: Worst Case | F5: Health Indicator
B6: Cash Opening Balance (₹ Cr) | C6: ='Data Entry'!C14 -> 0 | D6: ='Data Entry'!C14 -> 0 | E6: ='Data Entry'!C14 -> 0
B7: Monthly Revenue — Mo 1 (₹ Cr) | C7: ='Scenario Model'!C5 -> 0 | D7: ='Scenario Model'!P5 -> 0 | E7: ='Scenario Model'!AC5 -> 0
B8: Monthly Burn — Mo 1 (₹ Cr) | C8: ='Scenario Model'!C6 -> 0 | D8: ='Scenario Model'!P6 -> 0 | E8: ='Scenario Model'!AC6 -> 0
B9: Cash at Month 6 (₹ Cr) | C9: ='Scenario Model'!H10 -> 0 | D9: ='Scenario Model'!U10 -> 0 | E9: ='Scenario Model'!AH10 -> 0
B10: Cash at Month 12 (₹ Cr) | C10: ='Scenario Model'!N10 -> 0 | D10: ='Scenario Model'!AA10 -> 0 | E10: ='Scenario Model'!AN10 -> 0
B11: Estimated Runway | C11: =IFERROR(let(mn,MIN(IF(C10<=0,1,99),IF(D10<=0,2,99),IF(E10<=0,3,99),IF(F10<=0,4,99),IF(G10<=0,5,99),IF(H10<=0,6,99),IF(I10<=0,7,99),IF(J10<=0,8,99),IF(K10<=0,9,99),IF(L10<=0,10,99),IF(M10<=0,11,99),IF(N10<=0,12,99)),IF(mn=99,">12 months",mn&" months"))," — ") -> — | D11: =IFERROR(let(mn,MIN(IF(P10<=0,1,99),IF(Q10<=0,2,99),IF(R10<=0,3,99),IF(S10<=0,4,99),IF(T10<=0,5,99),IF(U10<=0,6,99),IF(V10<=0,7,99),IF(W10<=0,8,99),IF(X10<=0,9,99),IF(Y10<=0,10,99),IF(Z10<=0,11,99),IF(AA10<=0,12,99)),IF(mn=99,">12 months",mn&" months"))," — ") -> — | E11: =IFERROR(let(mn,MIN(IF(AC10<=0,1,99),IF(AD10<=0,2,99),IF(AE10<=0,3,99),IF(AF10<=0,4,99),IF(AG10<=0,5,99),IF(AH10<=0,6,99),IF(AI10<=0,7,99),IF(AJ10<=0,8,99),IF(AK10<=0,9,99),IF(AL10<=0,10,99),IF(AM10<=0,11,99),IF(AN10<=0,12,99)),IF(mn=99,">12 months",mn&" months"))," — ") -> — | F11: =IFERROR(IF(ISNUMBER(SEARCH("Stable",C11)),"🟢 Stable — >12 months",IF(ISNUMBER(SEARCH("Stable",D11)),"🟡 Downside still stable","🔴 Downside runway < 12 months")),"") -> 🔴 Downside runway < 12 months
B12: Net Burn Mo 1 (₹ Cr) | C12: =IFERROR('Scenario Model'!C6-'Scenario Model'!C5,0) -> 0 | D12: =IFERROR('Scenario Model'!P6-'Scenario Model'!P5,0) -> 0 | E12: =IFERROR('Scenario Model'!AC6-'Scenario Model'!AC5,0) -> 0 | F12: =IFERROR(IF(C12<=0,"🟢 Cash generative",IF(C12<'Data Entry'!C14*0.1,"🟡 Burn < 10% cash/mo","🔴 Burn is high relative to cash")),"") -> 🟢 Cash generative
B14: SCENARIO VERDICTS
B15: Scenario | C15: Runway | D15: Net Burn Mo 1 | E15: Cash @ Mo 12 | F15: Verdict
B16: 🟢 BASE CASE | C16: =IFERROR(let(mn,MIN(IF(C10<=0,1,99),IF(D10<=0,2,99),IF(E10<=0,3,99),IF(F10<=0,4,99),IF(G10<=0,5,99),IF(H10<=0,6,99),IF(I10<=0,7,99),IF(J10<=0,8,99),IF(K10<=0,9,99),IF(L10<=0,10,99),IF(M10<=0,11,99),IF(N10<=0,12,99)),IF(mn=99,">12 months",mn&" months"))," — ") -> — | D16: =IFERROR('Scenario Model'!C6-'Scenario Model'!C5,0) -> 0 | E16: ='Scenario Model'!N10 -> 0 | F16: =IFERROR(IF('Scenario Model'!N10>='Data Entry'!C14*0.5,"Strong — >50% opening cash remaining",IF('Scenario Model'!N10>0,"Caution — cash depleting","Critical — cash exhausted")),"") -> Strong — >50% opening cash remaining
B17: 🟡 DOWNSIDE | C17: =IFERROR(let(mn,MIN(IF(P10<=0,1,99),IF(Q10<=0,2,99),IF(R10<=0,3,99),IF(S10<=0,4,99),IF(T10<=0,5,99),IF(U10<=0,6,99),IF(V10<=0,7,99),IF(W10<=0,8,99),IF(X10<=0,9,99),IF(Y10<=0,10,99),IF(Z10<=0,11,99),IF(AA10<=0,12,99)),IF(mn=99,">12 months",mn&" months"))," — ") -> — | D17: =IFERROR('Scenario Model'!P6-'Scenario Model'!P5,0) -> 0 | E17: ='Scenario Model'!AA10 -> 0 | F17: =IFERROR(IF('Scenario Model'!AA10>='Data Entry'!C14*0.5,"Strong — >50% opening cash remaining",IF('Scenario Model'!AA10>0,"Caution — cash depleting","Critical — cash exhausted")),"") -> Strong — >50% opening cash remaining
B18: 🔴 WORST CASE | C18: =IFERROR(let(mn,MIN(IF(AC10<=0,1,99),IF(AD10<=0,2,99),IF(AE10<=0,3,99),IF(AF10<=0,4,99),IF(AG10<=0,5,99),IF(AH10<=0,6,99),IF(AI10<=0,7,99),IF(AJ10<=0,8,99),IF(AK10<=0,9,99),IF(AL10<=0,10,99),IF(AM10<=0,11,99),IF(AN10<=0,12,99)),IF(mn=99,">12 months",mn&" months"))," — ") -> — | D18: =IFERROR('Scenario Model'!AC6-'Scenario Model'!AC5,0) -> 0 | E18: ='Scenario Model'!AN10 -> 0 | F18: =IFERROR(IF('Scenario Model'!AN10>='Data Entry'!C14*0.5,"Strong — >50% opening cash remaining",IF('Scenario Model'!AN10>0,"Caution — cash depleting","Critical — cash exhausted")),"") -> Strong — >50% opening cash remaining
B20: ANALYST COMMENTARY
B21: Analyst: Overall cash position assessment — describe the business's runway risk under each scenario and flag the primary driver (revenue sensitivity, cost inflexibility, or scenario gap). Note any single largest risk.
B22: Analyst: Key recommendations — e.g. 'Downside scenario triggers a cash-out in Month 8. The primary intervention is reducing fixed burn by ₹X Cr per month through [specific cost]. Recommend initiating this review within 30 days regardless of base case outlook.'
B23: Analyst: Fundraising context — if a raise is planned, note whether the current runway supports completing it without distress pricing. Flag the deadline by which fundraising must close to avoid a crisis scenario.

Sheet Print Report
B1: PROFYT · Cash Runway Stress Test
B3: ='Data Entry'!C6 -> 0
B5: SECTION 1 — KEY INPUTS SUMMARY
B6: Metric | C6: Value | D6: Source
B7: Total Accessible Cash | C7: ='Data Entry'!C14 -> 0 | D7: 'Data Entry' Sheet · Section B
B8: Monthly Revenue | C8: ='Data Entry'!C23 -> 0 | D8: 'Data Entry' Sheet · Section C
B9: Monthly Burn | C9: ='Data Entry'!C35 -> 0 | D9: 'Data Entry' Sheet · Section D
B10: Net Monthly Burn | C10: =IFERROR('Data Entry'!C35-'Data Entry'!C23,0) -> 0 | D10: Calculated
B11: Revenue Growth Rate | C11: ='Data Entry'!C40 -> 0 | D11: 'Data Entry' Sheet · Section E
B12: Burn Growth Rate | C12: ='Data Entry'!C41 -> 0 | D12: 'Data Entry' Sheet · Section E
B14: SECTION 2 — SCENARIO RESULTS
B15: Scenario · Key Outcome | C15: Cash @ Mo 6 | D15: Cash @ Mo 12
B16: 🟢 BASE CASE — Client's own projections | C16: ='Scenario Model'!H10 -> 0 | D16: ='Scenario Model'!N10 -> 0
B17: 🟡 DOWNSIDE — Analyst stress scenario | C17: ='Scenario Model'!U10 -> 0 | D17: ='Scenario Model'!AA10 -> 0
B18: 🔴 WORST CASE — Maximum stress | C18: ='Scenario Model'!AH10 -> 0 | D18: ='Scenario Model'!AN10 -> 0
B21: SECTION 3 — ANALYST ASSESSMENT & RECOMMENDATIONS
B29: PROFYT · Confidential · This report is based on information provided by the client. PROFYT makes no warranty of accuracy.
